2023-07-04 17:51:29,468 [INFO] django.utils.autoreload: Watching for file changes with StatReloader
2023-07-04 17:51:59,948 [ERROR] django_jinja.builtins.extensions: Error: 'apporders' is not a registered namespace
2023-07-04 17:52:00,107 [ERROR] django.request: Internal Server Error: /cart/
Traceback (most recent call last):
  File "/home/user/PycharmProjects/python_django_team24/venv/lib/python3.10/site-packages/django/urls/base.py", line 71, in reverse
    extra, resolver = resolver.namespace_dict[ns]
KeyError: 'apporders'

During handling of the above exception, another exception occurred:

Traceback (most recent call last):
  File "/home/user/PycharmProjects/python_django_team24/venv/lib/python3.10/site-packages/django/core/handlers/exception.py", line 55, in inner
    response = get_response(request)
  File "/home/user/PycharmProjects/python_django_team24/venv/lib/python3.10/site-packages/django/core/handlers/base.py", line 197, in _get_response
    response = wrapped_callback(request, *callback_args, **callback_kwargs)
  File "/home/user/PycharmProjects/python_django_team24/app_cart/views.py", line 89, in cart_detail
    return render(request, 'cart/cart.jinja2', context=context)
  File "/home/user/PycharmProjects/python_django_team24/venv/lib/python3.10/site-packages/django/shortcuts.py", line 24, in render
    content = loader.render_to_string(template_name, context, request, using=using)
  File "/home/user/PycharmProjects/python_django_team24/venv/lib/python3.10/site-packages/django/template/loader.py", line 62, in render_to_string
    return template.render(context, request)
  File "/home/user/PycharmProjects/python_django_team24/venv/lib/python3.10/site-packages/django_jinja/backend.py", line 59, in render
    return mark_safe(self._process_template(self.template.render, context, request))
  File "/home/user/PycharmProjects/python_django_team24/venv/lib/python3.10/site-packages/django_jinja/backend.py", line 105, in _process_template
    return handler(context)
  File "/home/user/PycharmProjects/python_django_team24/venv/lib/python3.10/site-packages/jinja2/environment.py", line 1301, in render
    self.environment.handle_exception()
  File "/home/user/PycharmProjects/python_django_team24/venv/lib/python3.10/site-packages/jinja2/environment.py", line 936, in handle_exception
    raise rewrite_traceback_stack(source=source)
  File "/home/user/PycharmProjects/python_django_team24/templates/cart/cart.jinja2", line 1, in top-level template code
    {% extends 'base.jinja2' %}
  File "/home/user/PycharmProjects/python_django_team24/templates/base.jinja2", line 48, in top-level template code
    {% block body%}
  File "/home/user/PycharmProjects/python_django_team24/templates/cart/cart.jinja2", line 67, in block 'body'
    <div class="Cart-block"><a class="btn btn_success btn_lg" href={{ url("apporders:checkout_order")}}>Оформить заказ</a>
  File "/home/user/PycharmProjects/python_django_team24/venv/lib/python3.10/site-packages/django_jinja/builtins/extensions.py", line 190, in _url_reverse
    return reverse(name, args=args, kwargs=kwargs, current_app=current_app)
  File "/home/user/PycharmProjects/python_django_team24/venv/lib/python3.10/site-packages/django/urls/base.py", line 82, in reverse
    raise NoReverseMatch("%s is not a registered namespace" % key)
django.urls.exceptions.NoReverseMatch: 'apporders' is not a registered namespace
2023-07-04 17:52:46,612 [WARNING] django.request: Not Found: /sale/favicon.ico
2023-07-04 17:52:50,129 [ERROR] django.request: Internal Server Error: /
Traceback (most recent call last):
  File "/home/user/PycharmProjects/python_django_team24/venv/lib/python3.10/site-packages/django/db/backends/utils.py", line 89, in _execute
    return self.cursor.execute(sql, params)
  File "/home/user/PycharmProjects/python_django_team24/venv/lib/python3.10/site-packages/django/db/backends/sqlite3/base.py", line 328, in execute
    return super().execute(query, params)
sqlite3.OperationalError: no such column: app_administrator_settingsmodel.price_express_delivery

The above exception was the direct cause of the following exception:

Traceback (most recent call last):
  File "/home/user/PycharmProjects/python_django_team24/venv/lib/python3.10/site-packages/django/core/handlers/exception.py", line 55, in inner
    response = get_response(request)
  File "/home/user/PycharmProjects/python_django_team24/venv/lib/python3.10/site-packages/django/core/handlers/base.py", line 197, in _get_response
    response = wrapped_callback(request, *callback_args, **callback_kwargs)
  File "/home/user/PycharmProjects/python_django_team24/app_main_page/views.py", line 23, in main_page
    top_products = get_top_products()
  File "/home/user/PycharmProjects/python_django_team24/app_main_page/services.py", line 46, in get_top_products
    value_popular_products = getattr(SettingsModel.objects.first(), 'popular_products')
  File "/home/user/PycharmProjects/python_django_team24/venv/lib/python3.10/site-packages/django/db/models/manager.py", line 87, in manager_method
    return getattr(self.get_queryset(), name)(*args, **kwargs)
  File "/home/user/PycharmProjects/python_django_team24/venv/lib/python3.10/site-packages/django/db/models/query.py", line 1057, in first
    for obj in queryset[:1]:
  File "/home/user/PycharmProjects/python_django_team24/venv/lib/python3.10/site-packages/django/db/models/query.py", line 398, in __iter__
    self._fetch_all()
  File "/home/user/PycharmProjects/python_django_team24/venv/lib/python3.10/site-packages/django/db/models/query.py", line 1881, in _fetch_all
    self._result_cache = list(self._iterable_class(self))
  File "/home/user/PycharmProjects/python_django_team24/venv/lib/python3.10/site-packages/django/db/models/query.py", line 91, in __iter__
    results = compiler.execute_sql(
  File "/home/user/PycharmProjects/python_django_team24/venv/lib/python3.10/site-packages/django/db/models/sql/compiler.py", line 1560, in execute_sql
    cursor.execute(sql, params)
  File "/home/user/PycharmProjects/python_django_team24/venv/lib/python3.10/site-packages/django/db/backends/utils.py", line 102, in execute
    return super().execute(sql, params)
  File "/home/user/PycharmProjects/python_django_team24/venv/lib/python3.10/site-packages/django/db/backends/utils.py", line 67, in execute
    return self._execute_with_wrappers(
  File "/home/user/PycharmProjects/python_django_team24/venv/lib/python3.10/site-packages/django/db/backends/utils.py", line 80, in _execute_with_wrappers
    return executor(sql, params, many, context)
  File "/home/user/PycharmProjects/python_django_team24/venv/lib/python3.10/site-packages/django/db/backends/utils.py", line 84, in _execute
    with self.db.wrap_database_errors:
  File "/home/user/PycharmProjects/python_django_team24/venv/lib/python3.10/site-packages/django/db/utils.py", line 91, in __exit__
    raise dj_exc_value.with_traceback(traceback) from exc_value
  File "/home/user/PycharmProjects/python_django_team24/venv/lib/python3.10/site-packages/django/db/backends/utils.py", line 89, in _execute
    return self.cursor.execute(sql, params)
  File "/home/user/PycharmProjects/python_django_team24/venv/lib/python3.10/site-packages/django/db/backends/sqlite3/base.py", line 328, in execute
    return super().execute(query, params)
django.db.utils.OperationalError: no such column: app_administrator_settingsmodel.price_express_delivery
2023-07-04 17:53:49,390 [WARNING] django.request: Not Found: /assets/img/content/home/videoca.png
2023-07-04 17:53:53,091 [WARNING] django.request: Not Found: /assets/img/content/home/videoca.png
2023-07-04 17:54:02,857 [WARNING] django.request: Not Found: /assets/img/content/home/videoca.png
2023-07-04 17:54:05,360 [ERROR] django_jinja.builtins.extensions: Error: 'apporders' is not a registered namespace
2023-07-04 17:54:05,468 [ERROR] django.request: Internal Server Error: /cart/
Traceback (most recent call last):
  File "/home/user/PycharmProjects/python_django_team24/venv/lib/python3.10/site-packages/django/urls/base.py", line 71, in reverse
    extra, resolver = resolver.namespace_dict[ns]
KeyError: 'apporders'

During handling of the above exception, another exception occurred:

Traceback (most recent call last):
  File "/home/user/PycharmProjects/python_django_team24/venv/lib/python3.10/site-packages/django/core/handlers/exception.py", line 55, in inner
    response = get_response(request)
  File "/home/user/PycharmProjects/python_django_team24/venv/lib/python3.10/site-packages/django/core/handlers/base.py", line 197, in _get_response
    response = wrapped_callback(request, *callback_args, **callback_kwargs)
  File "/home/user/PycharmProjects/python_django_team24/app_cart/views.py", line 89, in cart_detail
    return render(request, 'cart/cart.jinja2', context=context)
  File "/home/user/PycharmProjects/python_django_team24/venv/lib/python3.10/site-packages/django/shortcuts.py", line 24, in render
    content = loader.render_to_string(template_name, context, request, using=using)
  File "/home/user/PycharmProjects/python_django_team24/venv/lib/python3.10/site-packages/django/template/loader.py", line 62, in render_to_string
    return template.render(context, request)
  File "/home/user/PycharmProjects/python_django_team24/venv/lib/python3.10/site-packages/django_jinja/backend.py", line 59, in render
    return mark_safe(self._process_template(self.template.render, context, request))
  File "/home/user/PycharmProjects/python_django_team24/venv/lib/python3.10/site-packages/django_jinja/backend.py", line 105, in _process_template
    return handler(context)
  File "/home/user/PycharmProjects/python_django_team24/venv/lib/python3.10/site-packages/jinja2/environment.py", line 1301, in render
    self.environment.handle_exception()
  File "/home/user/PycharmProjects/python_django_team24/venv/lib/python3.10/site-packages/jinja2/environment.py", line 936, in handle_exception
    raise rewrite_traceback_stack(source=source)
  File "/home/user/PycharmProjects/python_django_team24/templates/cart/cart.jinja2", line 1, in top-level template code
    {% extends 'base.jinja2' %}
  File "/home/user/PycharmProjects/python_django_team24/templates/base.jinja2", line 48, in top-level template code
    {% block body%}
  File "/home/user/PycharmProjects/python_django_team24/templates/cart/cart.jinja2", line 67, in block 'body'
    <div class="Cart-block"><a class="btn btn_success btn_lg" href={{ url("apporders:checkout_order")}}>Оформить заказ</a>
  File "/home/user/PycharmProjects/python_django_team24/venv/lib/python3.10/site-packages/django_jinja/builtins/extensions.py", line 190, in _url_reverse
    return reverse(name, args=args, kwargs=kwargs, current_app=current_app)
  File "/home/user/PycharmProjects/python_django_team24/venv/lib/python3.10/site-packages/django/urls/base.py", line 82, in reverse
    raise NoReverseMatch("%s is not a registered namespace" % key)
django.urls.exceptions.NoReverseMatch: 'apporders' is not a registered namespace
2023-07-04 17:56:52,354 [WARNING] django.request: Not Found: /assets/img/content/home/videoca.png
2023-07-04 17:56:53,780 [ERROR] django_jinja.builtins.extensions: Error: 'apporders' is not a registered namespace
2023-07-04 17:56:53,845 [ERROR] django.request: Internal Server Error: /cart/
Traceback (most recent call last):
  File "/home/user/PycharmProjects/python_django_team24/venv/lib/python3.10/site-packages/django/urls/base.py", line 71, in reverse
    extra, resolver = resolver.namespace_dict[ns]
KeyError: 'apporders'

During handling of the above exception, another exception occurred:

Traceback (most recent call last):
  File "/home/user/PycharmProjects/python_django_team24/venv/lib/python3.10/site-packages/django/core/handlers/exception.py", line 55, in inner
    response = get_response(request)
  File "/home/user/PycharmProjects/python_django_team24/venv/lib/python3.10/site-packages/django/core/handlers/base.py", line 197, in _get_response
    response = wrapped_callback(request, *callback_args, **callback_kwargs)
  File "/home/user/PycharmProjects/python_django_team24/app_cart/views.py", line 89, in cart_detail
    return render(request, 'cart/cart.jinja2', context=context)
  File "/home/user/PycharmProjects/python_django_team24/venv/lib/python3.10/site-packages/django/shortcuts.py", line 24, in render
    content = loader.render_to_string(template_name, context, request, using=using)
  File "/home/user/PycharmProjects/python_django_team24/venv/lib/python3.10/site-packages/django/template/loader.py", line 62, in render_to_string
    return template.render(context, request)
  File "/home/user/PycharmProjects/python_django_team24/venv/lib/python3.10/site-packages/django_jinja/backend.py", line 59, in render
    return mark_safe(self._process_template(self.template.render, context, request))
  File "/home/user/PycharmProjects/python_django_team24/venv/lib/python3.10/site-packages/django_jinja/backend.py", line 105, in _process_template
    return handler(context)
  File "/home/user/PycharmProjects/python_django_team24/venv/lib/python3.10/site-packages/jinja2/environment.py", line 1301, in render
    self.environment.handle_exception()
  File "/home/user/PycharmProjects/python_django_team24/venv/lib/python3.10/site-packages/jinja2/environment.py", line 936, in handle_exception
    raise rewrite_traceback_stack(source=source)
  File "/home/user/PycharmProjects/python_django_team24/templates/cart/cart.jinja2", line 1, in top-level template code
    {% extends 'base.jinja2' %}
  File "/home/user/PycharmProjects/python_django_team24/templates/base.jinja2", line 48, in top-level template code
    {% block body%}
  File "/home/user/PycharmProjects/python_django_team24/templates/cart/cart.jinja2", line 67, in block 'body'
    <div class="Cart-block"><a class="btn btn_success btn_lg" href={{ url("apporders:checkout_order")}}>Оформить заказ</a>
  File "/home/user/PycharmProjects/python_django_team24/venv/lib/python3.10/site-packages/django_jinja/builtins/extensions.py", line 190, in _url_reverse
    return reverse(name, args=args, kwargs=kwargs, current_app=current_app)
  File "/home/user/PycharmProjects/python_django_team24/venv/lib/python3.10/site-packages/django/urls/base.py", line 82, in reverse
    raise NoReverseMatch("%s is not a registered namespace" % key)
django.urls.exceptions.NoReverseMatch: 'apporders' is not a registered namespace
2023-07-04 18:02:01,083 [INFO] django.utils.autoreload: Watching for file changes with StatReloader
2023-07-04 18:02:16,529 [WARNING] django.request: Not Found: /assets/img/content/home/videoca.png
2023-07-04 18:02:16,657 [WARNING] django.request: Not Found: /assets/img/content/home/videoca.png
2023-07-04 18:02:20,282 [ERROR] django_jinja.builtins.extensions: Error: 'apporders' is not a registered namespace
2023-07-04 18:02:20,371 [ERROR] django.request: Internal Server Error: /cart/
Traceback (most recent call last):
  File "/home/user/PycharmProjects/python_django_team24/venv/lib/python3.10/site-packages/django/urls/base.py", line 71, in reverse
    extra, resolver = resolver.namespace_dict[ns]
KeyError: 'apporders'

During handling of the above exception, another exception occurred:

Traceback (most recent call last):
  File "/home/user/PycharmProjects/python_django_team24/venv/lib/python3.10/site-packages/django/core/handlers/exception.py", line 55, in inner
    response = get_response(request)
  File "/home/user/PycharmProjects/python_django_team24/venv/lib/python3.10/site-packages/django/core/handlers/base.py", line 197, in _get_response
    response = wrapped_callback(request, *callback_args, **callback_kwargs)
  File "/home/user/PycharmProjects/python_django_team24/app_cart/views.py", line 89, in cart_detail
    return render(request, 'cart/cart.jinja2', context=context)
  File "/home/user/PycharmProjects/python_django_team24/venv/lib/python3.10/site-packages/django/shortcuts.py", line 24, in render
    content = loader.render_to_string(template_name, context, request, using=using)
  File "/home/user/PycharmProjects/python_django_team24/venv/lib/python3.10/site-packages/django/template/loader.py", line 62, in render_to_string
    return template.render(context, request)
  File "/home/user/PycharmProjects/python_django_team24/venv/lib/python3.10/site-packages/django_jinja/backend.py", line 59, in render
    return mark_safe(self._process_template(self.template.render, context, request))
  File "/home/user/PycharmProjects/python_django_team24/venv/lib/python3.10/site-packages/django_jinja/backend.py", line 105, in _process_template
    return handler(context)
  File "/home/user/PycharmProjects/python_django_team24/venv/lib/python3.10/site-packages/jinja2/environment.py", line 1301, in render
    self.environment.handle_exception()
  File "/home/user/PycharmProjects/python_django_team24/venv/lib/python3.10/site-packages/jinja2/environment.py", line 936, in handle_exception
    raise rewrite_traceback_stack(source=source)
  File "/home/user/PycharmProjects/python_django_team24/templates/cart/cart.jinja2", line 1, in top-level template code
    {% extends 'base.jinja2' %}
  File "/home/user/PycharmProjects/python_django_team24/templates/base.jinja2", line 48, in top-level template code
    {% block body%}
  File "/home/user/PycharmProjects/python_django_team24/templates/cart/cart.jinja2", line 67, in block 'body'
    <div class="Cart-block"><a class="btn btn_success btn_lg" href={{ url("apporders:checkout_order")}}>Оформить заказ</a>
  File "/home/user/PycharmProjects/python_django_team24/venv/lib/python3.10/site-packages/django_jinja/builtins/extensions.py", line 190, in _url_reverse
    return reverse(name, args=args, kwargs=kwargs, current_app=current_app)
  File "/home/user/PycharmProjects/python_django_team24/venv/lib/python3.10/site-packages/django/urls/base.py", line 82, in reverse
    raise NoReverseMatch("%s is not a registered namespace" % key)
django.urls.exceptions.NoReverseMatch: 'apporders' is not a registered namespace
2023-07-04 18:03:18,300 [ERROR] django_jinja.builtins.extensions: Error: 'apporders' is not a registered namespace
2023-07-04 18:03:18,651 [ERROR] django.request: Internal Server Error: /cart/
Traceback (most recent call last):
  File "/home/user/PycharmProjects/python_django_team24/venv/lib/python3.10/site-packages/django/urls/base.py", line 71, in reverse
    extra, resolver = resolver.namespace_dict[ns]
KeyError: 'apporders'

During handling of the above exception, another exception occurred:

Traceback (most recent call last):
  File "/home/user/PycharmProjects/python_django_team24/venv/lib/python3.10/site-packages/django/core/handlers/exception.py", line 55, in inner
    response = get_response(request)
  File "/home/user/PycharmProjects/python_django_team24/venv/lib/python3.10/site-packages/django/core/handlers/base.py", line 197, in _get_response
    response = wrapped_callback(request, *callback_args, **callback_kwargs)
  File "/home/user/PycharmProjects/python_django_team24/app_cart/views.py", line 89, in cart_detail
    return render(request, 'cart/cart.jinja2', context=context)
  File "/home/user/PycharmProjects/python_django_team24/venv/lib/python3.10/site-packages/django/shortcuts.py", line 24, in render
    content = loader.render_to_string(template_name, context, request, using=using)
  File "/home/user/PycharmProjects/python_django_team24/venv/lib/python3.10/site-packages/django/template/loader.py", line 62, in render_to_string
    return template.render(context, request)
  File "/home/user/PycharmProjects/python_django_team24/venv/lib/python3.10/site-packages/django_jinja/backend.py", line 59, in render
    return mark_safe(self._process_template(self.template.render, context, request))
  File "/home/user/PycharmProjects/python_django_team24/venv/lib/python3.10/site-packages/django_jinja/backend.py", line 105, in _process_template
    return handler(context)
  File "/home/user/PycharmProjects/python_django_team24/venv/lib/python3.10/site-packages/jinja2/environment.py", line 1301, in render
    self.environment.handle_exception()
  File "/home/user/PycharmProjects/python_django_team24/venv/lib/python3.10/site-packages/jinja2/environment.py", line 936, in handle_exception
    raise rewrite_traceback_stack(source=source)
  File "/home/user/PycharmProjects/python_django_team24/templates/cart/cart.jinja2", line 1, in top-level template code
    {% extends 'base.jinja2' %}
  File "/home/user/PycharmProjects/python_django_team24/templates/base.jinja2", line 48, in top-level template code
    {% block body%}
  File "/home/user/PycharmProjects/python_django_team24/templates/cart/cart.jinja2", line 67, in block 'body'
    <div class="Cart-block"><a class="btn btn_success btn_lg" href={{ url("apporders:checkout_order")}}>Оформить заказ</a>
  File "/home/user/PycharmProjects/python_django_team24/venv/lib/python3.10/site-packages/django_jinja/builtins/extensions.py", line 190, in _url_reverse
    return reverse(name, args=args, kwargs=kwargs, current_app=current_app)
  File "/home/user/PycharmProjects/python_django_team24/venv/lib/python3.10/site-packages/django/urls/base.py", line 82, in reverse
    raise NoReverseMatch("%s is not a registered namespace" % key)
django.urls.exceptions.NoReverseMatch: 'apporders' is not a registered namespace
2023-07-04 18:03:24,266 [WARNING] django.request: Not Found: /assets/img/content/home/videoca.png
2023-07-04 18:03:24,353 [WARNING] django.request: Not Found: /assets/img/content/home/videoca.png
2023-07-04 18:04:18,461 [ERROR] django_jinja.builtins.extensions: Error: 'apporders' is not a registered namespace
2023-07-04 18:04:18,534 [ERROR] django.request: Internal Server Error: /cart/
Traceback (most recent call last):
  File "/home/user/PycharmProjects/python_django_team24/venv/lib/python3.10/site-packages/django/urls/base.py", line 71, in reverse
    extra, resolver = resolver.namespace_dict[ns]
KeyError: 'apporders'

During handling of the above exception, another exception occurred:

Traceback (most recent call last):
  File "/home/user/PycharmProjects/python_django_team24/venv/lib/python3.10/site-packages/django/core/handlers/exception.py", line 55, in inner
    response = get_response(request)
  File "/home/user/PycharmProjects/python_django_team24/venv/lib/python3.10/site-packages/django/core/handlers/base.py", line 197, in _get_response
    response = wrapped_callback(request, *callback_args, **callback_kwargs)
  File "/home/user/PycharmProjects/python_django_team24/app_cart/views.py", line 89, in cart_detail
    return render(request, 'cart/cart.jinja2', context=context)
  File "/home/user/PycharmProjects/python_django_team24/venv/lib/python3.10/site-packages/django/shortcuts.py", line 24, in render
    content = loader.render_to_string(template_name, context, request, using=using)
  File "/home/user/PycharmProjects/python_django_team24/venv/lib/python3.10/site-packages/django/template/loader.py", line 62, in render_to_string
    return template.render(context, request)
  File "/home/user/PycharmProjects/python_django_team24/venv/lib/python3.10/site-packages/django_jinja/backend.py", line 59, in render
    return mark_safe(self._process_template(self.template.render, context, request))
  File "/home/user/PycharmProjects/python_django_team24/venv/lib/python3.10/site-packages/django_jinja/backend.py", line 105, in _process_template
    return handler(context)
  File "/home/user/PycharmProjects/python_django_team24/venv/lib/python3.10/site-packages/jinja2/environment.py", line 1301, in render
    self.environment.handle_exception()
  File "/home/user/PycharmProjects/python_django_team24/venv/lib/python3.10/site-packages/jinja2/environment.py", line 936, in handle_exception
    raise rewrite_traceback_stack(source=source)
  File "/home/user/PycharmProjects/python_django_team24/templates/cart/cart.jinja2", line 1, in top-level template code
    {% extends 'base.jinja2' %}
  File "/home/user/PycharmProjects/python_django_team24/templates/base.jinja2", line 48, in top-level template code
    {% block body%}
  File "/home/user/PycharmProjects/python_django_team24/templates/cart/cart.jinja2", line 67, in block 'body'
    <div class="Cart-block"><a class="btn btn_success btn_lg" href="{{ url("apporders:checkout_order")}}">Оформить заказ</a>
  File "/home/user/PycharmProjects/python_django_team24/venv/lib/python3.10/site-packages/django_jinja/builtins/extensions.py", line 190, in _url_reverse
    return reverse(name, args=args, kwargs=kwargs, current_app=current_app)
  File "/home/user/PycharmProjects/python_django_team24/venv/lib/python3.10/site-packages/django/urls/base.py", line 82, in reverse
    raise NoReverseMatch("%s is not a registered namespace" % key)
django.urls.exceptions.NoReverseMatch: 'apporders' is not a registered namespace
2023-07-04 18:10:44,016 [INFO] django.utils.autoreload: /home/user/PycharmProjects/python_django_team24/config/urls.py changed, reloading.
2023-07-04 18:10:44,563 [INFO] django.utils.autoreload: Watching for file changes with StatReloader
2023-07-04 18:10:58,174 [WARNING] django.request: Not Found: /orders/checkout/favicon.ico
2023-07-04 18:13:05,949 [ERROR] django.request: Internal Server Error: /cart/
Traceback (most recent call last):
  File "/home/user/PycharmProjects/python_django_team24/venv/lib/python3.10/site-packages/django/core/handlers/exception.py", line 55, in inner
    response = get_response(request)
  File "/home/user/PycharmProjects/python_django_team24/venv/lib/python3.10/site-packages/django/utils/deprecation.py", line 136, in __call__
    response = self.process_response(request, response)
  File "/home/user/PycharmProjects/python_django_team24/venv/lib/python3.10/site-packages/django/contrib/sessions/middleware.py", line 59, in process_response
    request.session.save()
  File "/home/user/PycharmProjects/python_django_team24/venv/lib/python3.10/site-packages/django/contrib/sessions/backends/signed_cookies.py", line 39, in save
    self._session_key = self._get_session_key()
  File "/home/user/PycharmProjects/python_django_team24/venv/lib/python3.10/site-packages/django/contrib/sessions/backends/signed_cookies.py", line 72, in _get_session_key
    return signing.dumps(
  File "/home/user/PycharmProjects/python_django_team24/venv/lib/python3.10/site-packages/django/core/signing.py", line 152, in dumps
    return TimestampSigner(key=key, salt=salt).sign_object(
  File "/home/user/PycharmProjects/python_django_team24/venv/lib/python3.10/site-packages/django/core/signing.py", line 250, in sign_object
    data = serializer().dumps(obj)
  File "/home/user/PycharmProjects/python_django_team24/venv/lib/python3.10/site-packages/django/core/signing.py", line 127, in dumps
    return json.dumps(obj, separators=(",", ":")).encode("latin-1")
  File "/usr/lib/python3.10/json/__init__.py", line 238, in dumps
    **kw).encode(obj)
  File "/usr/lib/python3.10/json/encoder.py", line 199, in encode
    chunks = self.iterencode(o, _one_shot=True)
  File "/usr/lib/python3.10/json/encoder.py", line 257, in iterencode
    return _iterencode(o, 0)
  File "/usr/lib/python3.10/json/encoder.py", line 179, in default
    raise TypeError(f'Object of type {o.__class__.__name__} '
TypeError: Object of type ProductInShop is not JSON serializable
